Workbook

Sheet Instructivo
A1: CONTROL DE STOCK SEMANAL — COMO USAR ESTE LIBRO
A2: Candela Cafe & Patisserie · Prueba de 1 semana · 6 areas de produccion, 159 insumos, 141 productos
A3: Leer esta hoja antes de imprimir nada. Toma 5 minutos y evita una semana perdida.
B5: QUE RESPONDE ESTE LIBRO
B6: Cuanto insumo hay, cuanto se consumio de verdad en la semana, y si ese consumo se explica con lo que se elaboro. Lo que no se explica queda a la vista, separado en cuatro causas posibles: mal uso del insumo (rinde menos de lo que deberia), consumo del personal sin registrar, insumo que desaparece, y producto que se quema o se tira.
B7: ANTES DE ARRANCAR (el domingo previo, 1 hora)
B8: • 1. Hoja CONFIG: poner la fecha del lunes de arranque y el nombre del jefe de cada area. Todas las fechas del libro se completan solas.
B9: • 2. Hoja INSUMOS: revisar UNIDAD BASE y CONTENIDO POR BULTO de los 159 insumos. Los puse inferidos del nombre (ej. "Harina 000 x25kg" -> 25 kg por bulto) pero hay que confirmarlos contra el envase real. Si esto esta mal, todo el analisis sale mal.
B10: • 3. Hoja INSUMOS, columna CRITICO: vienen 62 marcados como SI (los caros y los de mayor riesgo). Esos son los unicos que se cuentan todos los dias. Sumar o quitar los que hagan falta.
B11: • 4. Imprimir: la planilla 1 (una por area, usando el filtro de AREA), la planilla 2, la planilla 3 (una por area) y la planilla 4 de cada area.
B12: DURANTE LA SEMANA
B13: • LUNES TEMPRANO, antes de producir — PLANILLA 1 (Inventario inicial): cada jefe de area cuenta TODOS sus insumos. Bultos cerrados + lo que hay suelto del envase abierto. La planilla calcula el total.
B14: • TODOS LOS DIAS, cuando entra mercaderia — PLANILLA 2 (Ingresos): quien recibe anota area, insumo, cantidad y numero de remito. En el momento, no despues. Un ingreso no anotado aparece al final como un faltante que no existe.
B15: • TODOS LOS DIAS, al cierre de la jornada — PLANILLA 3 (Conteo diario): cada jefe cuenta solo sus insumos criticos (unos 10). Son 5 minutos.
B16: • TODOS LOS DIAS, mientras se produce — PLANILLA 4 (Produccion diaria): el jefe de area anota lo ELABORADO y lo DESCARTADO de cada producto. Una planilla por area, ya con los productos del catalogo impresos.
... B29: COMO INTERPRETAR CADA SENAL
B30: SENAL EN LA PLANILLA | D30: LO QUE PROBABLEMENTE SIGNIFICA | F30: QUE HACER
B31: Consumo real muy por encima del de Fudo, parejo toda la semana | D31: La receta rinde menos de lo que dice la ficha tecnica, o se desperdicia en el proceso | F31: Pesar una produccion completa y recalcular la ficha
B32: Consumo real alto pero concentrado en 1 o 2 dias | D32: Un evento puntual: una tanda perdida, un derrame, o un retiro no registrado | F32: Cruzar con la planilla 5 y con quien estuvo de turno ese dia
B33: Consumo negativo (el stock final es mayor al posible) | D33: Entro mercaderia que nadie anoto en la planilla 2 | F33: Buscar el remito y reforzar el registro de ingresos
B34: Diferencia sin explicar positiva y grande en un producto | D34: Salio producto sin venderse ni registrarse: consumo del personal o faltante | F34: Comparar con Fudo consumos internos y con el sobrante en exhibicion
B35: Descarte declarado muy por debajo de lo que se ve en el piso | D35: No se esta anotando lo que se tira | F35: Insistir en la planilla 5: sin motivo cargado, todo se lee como faltante
B36: Lo recibido no coincide con la factura | D36: Se factura mas de lo que entra, o se recibe sin controlar | F36: Reclamar al proveedor y pesar en la recepcion
B37: LIMITES DE ESTE METODO (para no sacar conclusiones de mas)
B38: NO se lleva stock de producto terminado. La diferencia del analisis B incluye lo que quedo en exhibicion al cierre del domingo. Lea la tendencia y los casos grandes, no el numero exacto de cada producto.
B39: Una sola semana no distingue una causa estable de una casualidad. Sirve para senalar donde mirar, no para acusar a nadie.
B40: La calidad del resultado depende del conteo. Si el inventario inicial se hace "a ojo", el libro devuelve numeros prolijos y falsos.
B41: Cocina San Luis no tiene productos en el catalogo de la app: su planilla 4 viene en blanco para escribirlos a mano.
B42: REGLA DE ORO
B43: Solo se escribe en las celdas AMARILLAS. Todo lo que esta en negro o en verde es formula: si se pisa, se rompe el analisis.

Sheet Config
A1: CONFIGURACION DE LA SEMANA DE CONTROL
A2: Candela Cafe & Patisserie · Complete SOLO las celdas amarillas. Todo el libro se actualiza solo.
A3: Esta hoja alimenta las fechas y los desplegables del resto de las planillas.
A5: 1 · SEMANA DE CONTROL
A6: Fecha de inicio (lunes) | C6: Escriba la fecha del lunes en que arranca el control.
A7: Fecha de cierre (domingo) | B7: =IF($B$6="","",$B$6+6) | C7: Se calcula solo.
A9: DIA | B9: FECHA | C9: OBSERVACIONES DEL DIA
A10: Lunes | B10: =IF($B$6="","",$B$6+0)
A11: Martes | B11: =IF($B$6="","",$B$6+1)
A12: Miercoles | B12: =IF($B$6="","",$B$6+2)
A13: Jueves | B13: =IF($B$6="","",$B$6+3)
A14: Viernes | B14: =IF($B$6="","",$B$6+4)
A15: Sabado | B15: =IF($B$6="","",$B$6+5)
A16: Domingo | B16: =IF($B$6="","",$B$6+6)
A18: 2 · RESPONSABLES POR AREA
A19: AREA | B19: DONDE SE ELABORA | C19: JEFE DE AREA (nombre) | D19: FIRMA / ACLARACION
A20: Panadería | B20: Central
A21: Pastelería | B21: Central
A22: Especialidades | B22: Central
A23: Facturería | B23: Central
A24: Sandwiches | B24: Central
A25: Cocina San Luis | B25: Local San Luis
A27: 3 · MOTIVOS DE DESCARTE (desplegable en la hoja "5 Descartes")
A28: Quemado / mal cocido
A29: Mal armado / defectuoso
A30: Vencido / pasado
A31: Caido / roto
A32: Sobrante no vendido
A33: Prueba / degustacion
A34: Consumo del personal
A35: Devolucion de local
A36: Otro
A38: 4 · LEYENDA DE COLORES Y TIPOS DE LETRA
A39: Celda amarilla, letra azul | B39: La completa una persona a mano. Es el unico lugar donde hay que escribir.
A40: Letra negra, fondo blanco | B40: Formula. NO tocar: se calcula sola.
A41: Letra verde | B41: Trae el dato de otra hoja del libro. NO tocar.
A42: Fondo rojo claro | B42: Alerta: el desvio supera el limite tolerado. Hay que investigar.
A43: Fondo verde claro | B43: Dentro de lo esperado.
A45: 5 · LIMITES DE TOLERANCIA (para las alertas del Tablero)
A46: Desvio maximo tolerado en insumos (%) | B46: 0.05 | C46: Diferencia entre consumo real y consumo teorico/Fudo.
...

Sheet Insumos
A1: MAESTRO DE INSUMOS DE PRODUCCION
A2: Traido del catalogo real de la app de Pedidos de Produccion (159 insumos, 6 areas).
A3: REVISAR ANTES DE ARRANCAR: la unidad y el contenido por bulto fueron inferidos del nombre. Corrija lo que no coincida con el envase real.
A4: AREA | B4: INSUMO | C4: CATEGORIA | D4: PROVEEDOR | E4: UNIDAD BASE | F4: CONTENIDO POR BULTO | G4: CRITICO (conteo diario) | H4: COSTO POR UNIDAD $ | I4: CLAVE (no tocar)
A5: Panadería | B5: Aceite de girasol | E5: L | F5: 5 | G5: NO | I5: =$A5&" | "&$B5
A6: Panadería | B6: Aceite de oliva | E6: L | F6: 5 | G6: NO | I6: =$A6&" | "&$B6
A7: Panadería | B7: Aditivo | E7: kg | F7: 1 | G7: NO | I7: =$A7&" | "&$B7
A8: Panadería | B8: Avena | E8: kg | F8: 1 | G8: NO | I8: =$A8&" | "&$B8
A9: Panadería | B9: Azucar | E9: kg | F9: 1 | G9: SI | I9: =$A9&" | "&$B9
A10: Panadería | B10: Azucar impalpable | E10: kg | F10: 1 | G10: NO | I10: =$A10&" | "&$B10
A11: Panadería | B11: Berlina | E11: kg | F11: 1 | G11: NO | I11: =$A11&" | "&$B11
A12: Panadería | B12: Bicarbonato de amonio | E12: kg | F12: 1 | G12: NO | I12: =$A12&" | "&$B12
A13: Panadería | B13: Bicarbonato de sodio | E13: kg | F13: 1 | G13: NO | I13: =$A13&" | "&$B13
A14: Panadería | B14: Canela en polvo | E14: kg | F14: 1 | G14: NO | I14: =$A14&" | "&$B14
A15: Panadería | B15: Fecula | E15: kg | F15: 1 | G15: NO | I15: =$A15&" | "&$B15
A16: Panadería | B16: Grasa | E16: kg | F16: 1 | G16: SI | I16: =$A16&" | "&$B16
... A42: Panadería | B42: Albahaca | E42: kg | F42: 1 | G42: NO | I42: =$A42&" | "&$B42
A43: Panadería | B43: Tomates cherry | D43: Verdulería | E43: kg | F43: 1 | G43: NO | I43: =$A43&" | "&$B43
A44: Panadería | B44: Cebolla morada | D44: Verdulería | E44: kg | F44: 1 | G44: NO | I44: =$A44&" | "&$B44
A45: Panadería | B45: Albahaca hidropónica | D45: Verdulería | E45: kg | F45: 1 | G45: NO | I45: =$A45&" | "&$B45
A46: Panadería | B46: Rúcula | D46: Verdulería | E46: kg | F46: 1 | G46: NO | I46: =$A46&" | "&$B46
A47: Pastelería | B47: Almendras | E47: kg | F47: 1 | G47: SI | I47: =$A47&" | "&$B47
A48: Pastelería | B48: Arandanos congelados | E48: kg | F48: 1 | G48: SI | I48: =$A48&" | "&$B48
A49: Pastelería | B49: Azucar | E49: kg | F49: 1 | G49: SI | I49: =$A49&" | "&$B49
A50: Pastelería | B50: Azucar impalpable | E50: kg | F50: 1 | G50: NO | I50: =$A50&" | "&$B50
A51: Pastelería | B51: Baño alpino | E51: kg | F51: 1 | G51: SI | I51: =$A51&" | "&$B51
A52: Pastelería | B52: Baño lodiser semiamargo | E52: kg | F52: 1 | G52: SI | I52: =$A52&" | "&$B52
A53: Pastelería | B53: Cacao | E53: kg | F53: 1 | G53: NO | I53: =$A53&" | "&$B53
A54: Pastelería | B54: Chocolate chip | E54: kg | F54: 1 | G54: SI | I54: =$A54&" | "&$B54
A55: Pastelería | B55: Chocolate gotas | E55: kg | F55: 1 | G55: SI | I55: =$A55&" | "&$B55
A56: Pastelería | B56: Chocolate moldeo | E56: kg | F56: 1 | G56: SI | I56: =$A56&" | "&$B56
A57: Pastelería | B57: Coco rallado | E57: kg | F57: 1 | G57: NO | I57: =$A57&" | "&$B57
A58: Pastelería | B58: Confites mini | E58: kg | F58: 1 | G58: NO | I58: =$A58&" | "&$B58
... A84: Pastelería | B84: Variegato Maracuya | E84: L | F84: 1 | G84: NO | I84: =$A84&" | "&$B84
A85: Pastelería | B85: Frutilla | D85: Verdulería | E85: kg | F85: 1 | G85: NO | I85: =$A85&" | "&$B85
A86: Pastelería | B86: Arándanos | D86: Verdulería | E86: kg | F86: 1 | G86: NO | I86: =$A86&" | "&$B86
A87: Pastelería | B87: Limón | D87: Verdulería | E87: kg | F87: 1 | G87: NO | I87: =$A87&" | "&$B87
A88: Pastelería | B88: Durazno | D88: Verdulería | E88: kg | F88: 1 | G88: NO | I88: =$A88&" | "&$B88
A89: Pastelería | B89: Kiwi | D89: Verdulería | E89: kg | F89: 1 | G89: NO | I89: =$A89&" | "&$B89
A90: Pastelería | B90: Ananá | D90: Verdulería | E90: kg | F90: 1 | G90: NO | I90: =$A90&" | "&$B90
...

Sheet Productos
A1: MAESTRO DE PRODUCTOS ELABORADOS
A2: Traido del catalogo real de la app (141 productos).
A3: Cocina San Luis no tiene productos en el catalogo: se cargan a mano en su planilla de produccion.
A4: AREA | B4: PRODUCTO | C4: UNIDAD | D4: DONDE SE ELABORA | E4: CLAVE (no tocar)
A5: Panadería | B5: Bagel | C5: u | D5: Central | E5: =$A5&" | "&$B5
A6: Panadería | B6: Bizcochos | C6: kg | D6: Central | E6: =$A6&" | "&$B6
A7: Panadería | B7: Bizcochos de margarina | C7: kg | D7: Central | E7: =$A7&" | "&$B7
A8: Panadería | B8: Bizcochos redondos | C8: kg | D8: Central | E8: =$A8&" | "&$B8
A9: Panadería | B9: Bollitos B/N | C9: u | D9: Central | E9: =$A9&" | "&$B9
A10: Panadería | B10: Bollos grandes | C10: u | D10: Central | E10: =$A10&" | "&$B10
A11: Panadería | B11: Caseras | C11: u | D11: Central | E11: =$A11&" | "&$B11
A12: Panadería | B12: Caseritas | C12: u | D12: Central | E12: =$A12&" | "&$B12
A13: Panadería | B13: Chatas | C13: kg | D13: Central | E13: =$A13&" | "&$B13
A14: Panadería | B14: Cremona | C14: u | D14: Central | E14: =$A14&" | "&$B14
A15: Panadería | B15: Focaccia | C15: u | D15: Central | E15: =$A15&" | "&$B15
A16: Panadería | B16: Libritos | C16: u | D16: Central | E16: =$A16&" | "&$B16
... A145: Sandwiches | B145: Miga de cantimpalo y queso | C145: u | D145: Central | E145: =$A145&" | "&$B145

Sheet 1 Inv Inicial
A1: PLANILLA 1 · INVENTARIO INICIAL DE INSUMOS
A2: Se cuenta el LUNES antes de arrancar a producir. Una hoja por area: filtre por AREA e imprima.
A3: COMO CONTAR: bultos cerrados + lo que hay suelto del abierto. Ejemplo: 3 bolsas de 25 kg + 8,5 kg sueltos -> Bultos = 3, Parcial = 8,5, TOTAL = 83,5 kg (lo calcula la planilla).
A4: AREA | B4: INSUMO | C4: UNID. | D4: CONTENIDO POR BULTO | E4: BULTOS CERRADOS | F4: PARCIAL (suelto) | G4: TOTAL (calculado) | H4: CONTO (iniciales) | I4: OBSERVACIONES
A5: =Insumos!$A5 | B5: =Insumos!$B5 | C5: =Insumos!$E5 | D5: =Insumos!$F5 | G5: =IFERROR($E5*$D5,0)+IFERROR($F5,0)
A6: =Insumos!$A6 | B6: =Insumos!$B6 | C6: =Insumos!$E6 | D6: =Insumos!$F6 | G6: =IFERROR($E6*$D6,0)+IFERROR($F6,0)
A7: =Insumos!$A7 | B7: =Insumos!$B7 | C7: =Insumos!$E7 | D7: =Insumos!$F7 | G7: =IFERROR($E7*$D7,0)+IFERROR($F7,0)
A8: =Insumos!$A8 | B8: =Insumos!$B8 | C8: =Insumos!$E8 | D8: =Insumos!$F8 | G8: =IFERROR($E8*$D8,0)+IFERROR($F8,0)
A9: =Insumos!$A9 | B9: =Insumos!$B9 | C9: =Insumos!$E9 | D9: =Insumos!$F9 | G9: =IFERROR($E9*$D9,0)+IFERROR($F9,0)
A10: =Insumos!$A10 | B10: =Insumos!$B10 | C10: =Insumos!$E10 | D10: =Insumos!$F10 | G10: =IFERROR($E10*$D10,0)+IFERROR($F10,0)
A11: =Insumos!$A11 | B11: =Insumos!$B11 | C11: =Insumos!$E11 | D11: =Insumos!$F11 | G11: =IFERROR($E11*$D11,0)+IFERROR($F11,0)
A12: =Insumos!$A12 | B12: =Insumos!$B12 | C12: =Insumos!$E12 | D12: =Insumos!$F12 | G12: =IFERROR($E12*$D12,0)+IFERROR($F12,0)
A13: =Insumos!$A13 | B13: =Insumos!$B13 | C13: =Insumos!$E13 | D13: =Insumos!$F13 | G13: =IFERROR($E13*$D13,0)+IFERROR($F13,0)
A14: =Insumos!$A14 | B14: =Insumos!$B14 | C14: =Insumos!$E14 | D14: =Insumos!$F14 | G14: =IFERROR($E14*$D14,0)+IFERROR($F14,0)
A15: =Insumos!$A15 | B15: =Insumos!$B15 | C15: =Insumos!$E15 | D15: =Insumos!$F15 | G15: =IFERROR($E15*$D15,0)+IFERROR($F15,0)
A16: =Insumos!$A16 | B16: =Insumos!$B16 | C16: =Insumos!$E16 | D16: =Insumos!$F16 | G16: =IFERROR($E16*$D16,0)+IFERROR($F16,0)
... A163: =Insumos!$A163 | B163: =Insumos!$B163 | C163: =Insumos!$E163 | D163: =Insumos!$F163 | G163: =IFERROR($E163*$D163,0)+IFERROR($F163,0)

Sheet 2 Ingresos
A1: PLANILLA 2 · INGRESOS DE MERCADERIA DE LA SEMANA
A2: Se anota CADA VEZ que entra mercaderia a un area, en el momento en que entra. Sin esto no se puede calcular el consumo.
A3: La fila 5 es un EJEMPLO: borrela antes de empezar. Cargue desde la fila 6.
A4: FECHA | B4: AREA | C4: INSUMO | D4: PROVEEDOR | E4: N° REMITO / FACTURA | F4: BULTOS | G4: CONTENIDO POR BULTO | H4: PARCIAL | I4: TOTAL (calculado) | J4: RECIBIO (iniciales) | K4: CONTROL AUTOMATICO
A5: =IF(Config!$B$6="","",Config!$B$6) | B5: Panaderia | C5: Harina 000 x25kg | D5: Molino XX | E5: R-0001234 | F5: 4 | G5: =IFERROR(INDEX(Insumos!$F$5:$F$163,MATCH($B5&" | "&$C5,Insumos!$I$5:$I$163,0)),"") | H5: 12.5 | I5: =IFERROR($F5*$G5,0)+IFERROR($H5,0) | J5: JP | K5: EJEMPLO - borrar esta fila
G6: =IFERROR(INDEX(Insumos!$F$5:$F$163,MATCH($B6&" | "&$C6,Insumos!$I$5:$I$163,0)),"") | I6: =IFERROR($F6*$G6,0)+IFERROR($H6,0) | K6: =IF($C6="","",IF(COUNTIF(Insumos!$I$5:$I$163,$B6&" | "&$C6)=0,"REVISAR: area+insumo no existe en el maestro","OK"))
G7: =IFERROR(INDEX(Insumos!$F$5:$F$163,MATCH($B7&" | "&$C7,Insumos!$I$5:$I$163,0)),"") | I7: =IFERROR($F7*$G7,0)+IFERROR($H7,0) | K7: =IF($C7="","",IF(COUNTIF(Insumos!$I$5:$I$163,$B7&" | "&$C7)=0,"REVISAR: area+insumo no existe en el maestro","OK"))
G8: =IFERROR(INDEX(Insumos!$F$5:$F$163,MATCH($B8&" | "&$C8,Insumos!$I$5:$I$163,0)),"") | I8: =IFERROR($F8*$G8,0)+IFERROR($H8,0) | K8: =IF($C8="","",IF(COUNTIF(Insumos!$I$5:$I$163,$B8&" | "&$C8)=0,"REVISAR: area+insumo no existe en el maestro","OK"))
G9: =IFERROR(INDEX(Insumos!$F$5:$F$163,MATCH($B9&" | "&$C9,Insumos!$I$5:$I$163,0)),"") | I9: =IFERROR($F9*$G9,0)+IFERROR($H9,0) | K9: =IF($C9="","",IF(COUNTIF(Insumos!$I$5:$I$163,$B9&" | "&$C9)=0,"REVISAR: area+insumo no existe en el maestro","OK"))
G10: =IFERROR(INDEX(Insumos!$F$5:$F$163,MATCH($B10&" | "&$C10,Insumos!$I$5:$I$163,0)),"") | I10: =IFERROR($F10*$G10,0)+IFERROR($H10,0) | K10: =IF($C10="","",IF(COUNTIF(Insumos!$I$5:$I$163,$B10&" | "&$C10)=0,"REVISAR: area+insumo no existe en el maestro","OK"))
G11: =IFERROR(INDEX(Insumos!$F$5:$F$163,MATCH($B11&" | "&$C11,Insumos!$I$5:$I$163,0)),"") | I11: =IFERROR($F11*$G11,0)+IFERROR($H11,0) | K11: =IF($C11="","",IF(COUNTIF(Insumos!$I$5:$I$163,$B11&" | "&$C11)=0,"REVISAR: area+insumo no existe en el maestro","OK"))
G12: =IFERROR(INDEX(Insumos!$F$5:$F$163,MATCH($B12&" | "&$C12,Insumos!$I$5:$I$163,0)),"") | I12: =IFERROR($F12*$G12,0)+IFERROR($H12,0) | K12: =IF($C12="","",IF(COUNTIF(Insumos!$I$5:$I$163,$B12&" | "&$C12)=0,"REVISAR: area+insumo no existe en el maestro","OK"))
G13: =IFERROR(INDEX(Insumos!$F$5:$F$163,MATCH($B13&" | "&$C13,Insumos!$I$5:$I$163,0)),"") | I13: =IFERROR($F13*$G13,0)+IFERROR($H13,0) | K13: =IF($C13="","",IF(COUNTIF(Insumos!$I$5:$I$163,$B13&" | "&$C13)=0,"REVISAR: area+insumo no existe en el maestro","OK"))
G14: =IFERROR(INDEX(Insumos!$F$5:$F$163,MATCH($B14&" | "&$C14,Insumos!$I$5:$I$163,0)),"") | I14: =IFERROR($F14*$G14,0)+IFERROR($H14,0) | K14: =IF($C14="","",IF(COUNTIF(Insumos!$I$5:$I$163,$B14&" | "&$C14)=0,"REVISAR: area+insumo no existe en el maestro","OK"))
G15: =IFERROR(INDEX(Insumos!$F$5:$F$163,MATCH($B15&" | "&$C15,Insumos!$I$5:$I$163,0)),"") | I15: =IFERROR($F15*$G15,0)+IFERROR($H15,0) | K15: =IF($C15="","",IF(COUNTIF(Insumos!$I$5:$I$163,$B15&" | "&$C15)=0,"REVISAR: area+insumo no existe en el maestro","OK"))
G16: =IFERROR(INDEX(Insumos!$F$5:$F$163,MATCH($B16&" | "&$C16,Insumos!$I$5:$I$163,0)),"") | I16: =IFERROR($F16*$G16,0)+IFERROR($H16,0) | K16: =IF($C16="","",IF(COUNTIF(Insumos!$I$5:$I$163,$B16&" | "&$C16)=0,"REVISAR: area+insumo no existe en el maestro","OK"))
G17: =IFERROR(INDEX(Insumos!$F$5:$F$163,MATCH($B17&" | "&$C17,Insumos!$I$5:$I$163,0)),"") | I17: =IFERROR($F17*$G17,0)+IFERROR($H17,0) | K17: =IF($C17="","",IF(COUNTIF(Insumos!$I$5:$I$163,$B17&" | "&$C17)=0,"REVISAR: area+insumo no existe en el maestro","OK"))
... G255: =IFERROR(INDEX(Insumos!$F$5:$F$163,MATCH($B255&" | "&$C255,Insumos!$I$5:$I$163,0)),"") | I255: =IFERROR($F255*$G255,0)+IFERROR($H255,0) | K255: =IF($C255="","",IF(COUNTIF(Insumos!$I$5:$I$163,$B255&" | "&$C255)=0,"REVISAR: area+insumo no existe en el maestro","OK"))

Sheet 3 Conteo Diario
A1: PLANILLA 3 · CONTEO DIARIO DE INSUMOS CRITICOS
A2: Cada jefe de area cuenta SOLO sus insumos criticos, al cierre de su jornada. 62 insumos en total (unos 10 por area).
A3: Filtre por AREA e imprima una hoja por area. Mismo criterio que el inventario: bultos cerrados + suelto.
A4: AREA | B4: INSUMO | C4: UNID. | D4: CONTENIDO POR BULTO | E4: =IF(Config!$B$10="","LUNES",UPPER("LUN")&" "&TEXT(Config!$B$10,"dd/mm")) | G4: =IF(Config!$B$11="","MARTES",UPPER("MAR")&" "&TEXT(Config!$B$11,"dd/mm")) | I4: =IF(Config!$B$12="","MIERCOLES",UPPER("MIE")&" "&TEXT(Config!$B$12,"dd/mm")) | K4: =IF(Config!$B$13="","JUEVES",UPPER("JUE")&" "&TEXT(Config!$B$13,"dd/mm")) | M4: =IF(Config!$B$14="","VIERNES",UPPER("VIE")&" "&TEXT(Config!$B$14,"dd/mm")) | O4: =IF(Config!$B$15="","SABADO",UPPER("SAB")&" "&TEXT(Config!$B$15,"dd/mm")) | Q4: =IF(Config!$B$16="","DOMINGO",UPPER("DOM")&" "&TEXT(Config!$B$16,"dd/mm")) | S4: TOTAL LUN | T4: TOTAL MAR | U4: TOTAL MIE | V4: TOTAL JUE | W4: TOTAL VIE | X4: TOTAL SAB | Y4: TOTAL DOM
E5: Bultos | F5: Parcial | G5: Bultos | H5: Parcial | I5: Bultos | J5: Parcial | K5: Bultos | L5: Parcial | M5: Bultos | N5: Parcial | O5: Bultos | P5: Parcial | Q5: Bultos | R5: Parcial
A6: =Insumos!$A9 | B6: =Insumos!$B9 | C6: =Insumos!$E9 | D6: =Insumos!$F9 | S6: =IF(AND(E6="",F6=""),"",IFERROR(E6*$D6,0)+IFERROR(F6,0)) | T6: =IF(AND(G6="",H6=""),"",IFERROR(G6*$D6,0)+IFERROR(H6,0)) | U6: =IF(AND(I6="",J6=""),"",IFERROR(I6*$D6,0)+IFERROR(J6,0)) | V6: =IF(AND(K6="",L6=""),"",IFERROR(K6*$D6,0)+IFERROR(L6,0)) | W6: =IF(AND(M6="",N6=""),"",IFERROR(M6*$D6,0)+IFERROR(N6,0)) | X6: =IF(AND(O6="",P6=""),"",IFERROR(O6*$D6,0)+IFERROR(P6,0)) | Y6: =IF(AND(Q6="",R6=""),"",IFERROR(Q6*$D6,0)+IFERROR(R6,0))
A7: =Insumos!$A16 | B7: =Insumos!$B16 | C7: =Insumos!$E16 | D7: =Insumos!$F16 | S7: =IF(AND(E7="",F7=""),"",IFERROR(E7*$D7,0)+IFERROR(F7,0)) | T7: =IF(AND(G7="",H7=""),"",IFERROR(G7*$D7,0)+IFERROR(H7,0)) | U7: =IF(AND(I7="",J7=""),"",IFERROR(I7*$D7,0)+IFERROR(J7,0)) | V7: =IF(AND(K7="",L7=""),"",IFERROR(K7*$D7,0)+IFERROR(L7,0)) | W7: =IF(AND(M7="",N7=""),"",IFERROR(M7*$D7,0)+IFERROR(N7,0)) | X7: =IF(AND(O7="",P7=""),"",IFERROR(O7*$D7,0)+IFERROR(P7,0)) | Y7: =IF(AND(Q7="",R7=""),"",IFERROR(Q7*$D7,0)+IFERROR(R7,0))
A8: =Insumos!$A17 | B8: =Insumos!$B17 | C8: =Insumos!$E17 | D8: =Insumos!$F17 | S8: =IF(AND(E8="",F8=""),"",IFERROR(E8*$D8,0)+IFERROR(F8,0)) | T8: =IF(AND(G8="",H8=""),"",IFERROR(G8*$D8,0)+IFERROR(H8,0)) | U8: =IF(AND(I8="",J8=""),"",IFERROR(I8*$D8,0)+IFERROR(J8,0)) | V8: =IF(AND(K8="",L8=""),"",IFERROR(K8*$D8,0)+IFERROR(L8,0)) | W8: =IF(AND(M8="",N8=""),"",IFERROR(M8*$D8,0)+IFERROR(N8,0)) | X8: =IF(AND(O8="",P8=""),"",IFERROR(O8*$D8,0)+IFERROR(P8,0)) | Y8: =IF(AND(Q8="",R8=""),"",IFERROR(Q8*$D8,0)+IFERROR(R8,0))
A9: =Insumos!$A18 | B9: =Insumos!$B18 | C9: =Insumos!$E18 | D9: =Insumos!$F18 | S9: =IF(AND(E9="",F9=""),"",IFERROR(E9*$D9,0)+IFERROR(F9,0)) | T9: =IF(AND(G9="",H9=""),"",IFERROR(G9*$D9,0)+IFERROR(H9,0)) | U9: =IF(AND(I9="",J9=""),"",IFERROR(I9*$D9,0)+IFERROR(J9,0)) | V9: =IF(AND(K9="",L9=""),"",IFERROR(K9*$D9,0)+IFERROR(L9,0)) | W9: =IF(AND(M9="",N9=""),"",IFERROR(M9*$D9,0)+IFERROR(N9,0)) | X9: =IF(AND(O9="",P9=""),"",IFERROR(O9*$D9,0)+IFERROR(P9,0)) | Y9: =IF(AND(Q9="",R9=""),"",IFERROR(Q9*$D9,0)+IFERROR(R9,0))
A10: =Insumos!$A19 | B10: =Insumos!$B19 | C10: =Insumos!$E19 | D10: =Insumos!$F19 | S10: =IF(AND(E10="",F10=""),"",IFERROR(E10*$D10,0)+IFERROR(F10,0)) | T10: =IF(AND(G10="",H10=""),"",IFERROR(G10*$D10,0)+IFERROR(H10,0)) | U10: =IF(AND(I10="",J10=""),"",IFERROR(I10*$D10,0)+IFERROR(J10,0)) | V10: =IF(AND(K10="",L10=""),"",IFERROR(K10*$D10,0)+IFERROR(L10,0)) | W10: =IF(AND(M10="",N10=""),"",IFERROR(M10*$D10,0)+IFERROR(N10,0)) | X10: =IF(AND(O10="",P10=""),"",IFERROR(O10*$D10,0)+IFERROR(P10,0)) | Y10: =IF(AND(Q10="",R10=""),"",IFERROR(Q10*$D10,0)+IFERROR(R10,0))
A11: =Insumos!$A20 | B11: =Insumos!$B20 | C11: =Insumos!$E20 | D11: =Insumos!$F20 | S11: =IF(AND(E11="",F11=""),"",IFERROR(E11*$D11,0)+IFERROR(F11,0)) | T11: =IF(AND(G11="",H11=""),"",IFERROR(G11*$D11,0)+IFERROR(H11,0)) | U11: =IF(AND(I11="",J11=""),"",IFERROR(I11*$D11,0)+IFERROR(J11,0)) | V11: =IF(AND(K11="",L11=""),"",IFERROR(K11*$D11,0)+IFERROR(L11,0)) | W11: =IF(AND(M11="",N11=""),"",IFERROR(M11*$D11,0)+IFERROR(N11,0)) | X11: =IF(AND(O11="",P11=""),"",IFERROR(O11*$D11,0)+IFERROR(P11,0)) | Y11: =IF(AND(Q11="",R11=""),"",IFERROR(Q11*$D11,0)+IFERROR(R11,0))
A12: =Insumos!$A21 | B12: =Insumos!$B21 | C12: =Insumos!$E21 | D12: =Insumos!$F21 | S12: =IF(AND(E12="",F12=""),"",IFERROR(E12*$D12,0)+IFERROR(F12,0)) | T12: =IF(AND(G12="",H12=""),"",IFERROR(G12*$D12,0)+IFERROR(H12,0)) | U12: =IF(AND(I12="",J12=""),"",IFERROR(I12*$D12,0)+IFERROR(J12,0)) | V12: =IF(AND(K12="",L12=""),"",IFERROR(K12*$D12,0)+IFERROR(L12,0)) | W12: =IF(AND(M12="",N12=""),"",IFERROR(M12*$D12,0)+IFERROR(N12,0)) | X12: =IF(AND(O12="",P12=""),"",IFERROR(O12*$D12,0)+IFERROR(P12,0)) | Y12: =IF(AND(Q12="",R12=""),"",IFERROR(Q12*$D12,0)+IFERROR(R12,0))
A13: =Insumos!$A22 | B13: =Insumos!$B22 | C13: =Insumos!$E22 | D13: =Insumos!$F22 | S13: =IF(AND(E13="",F13=""),"",IFERROR(E13*$D13,0)+IFERROR(F13,0)) | T13: =IF(AND(G13="",H13=""),"",IFERROR(G13*$D13,0)+IFERROR(H13,0)) | U13: =IF(AND(I13="",J13=""),"",IFERROR(I13*$D13,0)+IFERROR(J13,0)) | V13: =IF(AND(K13="",L13=""),"",IFERROR(K13*$D13,0)+IFERROR(L13,0)) | W13: =IF(AND(M13="",N13=""),"",IFERROR(M13*$D13,0)+IFERROR(N13,0)) | X13: =IF(AND(O13="",P13=""),"",IFERROR(O13*$D13,0)+IFERROR(P13,0)) | Y13: =IF(AND(Q13="",R13=""),"",IFERROR(Q13*$D13,0)+IFERROR(R13,0))
A14: =Insumos!$A47 | B14: =Insumos!$B47 | C14: =Insumos!$E47 | D14: =Insumos!$F47 | S14: =IF(AND(E14="",F14=""),"",IFERROR(E14*$D14,0)+IFERROR(F14,0)) | T14: =IF(AND(G14="",H14=""),"",IFERROR(G14*$D14,0)+IFERROR(H14,0)) | U14: =IF(AND(I14="",J14=""),"",IFERROR(I14*$D14,0)+IFERROR(J14,0)) | V14: =IF(AND(K14="",L14=""),"",IFERROR(K14*$D14,0)+IFERROR(L14,0)) | W14: =IF(AND(M14="",N14=""),"",IFERROR(M14*$D14,0)+IFERROR(N14,0)) | X14: =IF(AND(O14="",P14=""),"",IFERROR(O14*$D14,0)+IFERROR(P14,0)) | Y14: =IF(AND(Q14="",R14=""),"",IFERROR(Q14*$D14,0)+IFERROR(R14,0))
A15: =Insumos!$A48 | B15: =Insumos!$B48 | C15: =Insumos!$E48 | D15: =Insumos!$F48 | S15: =IF(AND(E15="",F15=""),"",IFERROR(E15*$D15,0)+IFERROR(F15,0)) | T15: =IF(AND(G15="",H15=""),"",IFERROR(G15*$D15,0)+IFERROR(H15,0)) | U15: =IF(AND(I15="",J15=""),"",IFERROR(I15*$D15,0)+IFERROR(J15,0)) | V15: =IF(AND(K15="",L15=""),"",IFERROR(K15*$D15,0)+IFERROR(L15,0)) | W15: =IF(AND(M15="",N15=""),"",IFERROR(M15*$D15,0)+IFERROR(N15,0)) | X15: =IF(AND(O15="",P15=""),"",IFERROR(O15*$D15,0)+IFERROR(P15,0)) | Y15: =IF(AND(Q15="",R15=""),"",IFERROR(Q15*$D15,0)+IFERROR(R15,0))
A16: =Insumos!$A49 | B16: =Insumos!$B49 | C16: =Insumos!$E49 | D16: =Insumos!$F49 | S16: =IF(AND(E16="",F16=""),"",IFERROR(E16*$D16,0)+IFERROR(F16,0)) | T16: =IF(AND(G16="",H16=""),"",IFERROR(G16*$D16,0)+IFERROR(H16,0)) | U16: =IF(AND(I16="",J16=""),"",IFERROR(I16*$D16,0)+IFERROR(J16,0)) | V16: =IF(AND(K16="",L16=""),"",IFERROR(K16*$D16,0)+IFERROR(L16,0)) | W16: =IF(AND(M16="",N16=""),"",IFERROR(M16*$D16,0)+IFERROR(N16,0)) | X16: =IF(AND(O16="",P16=""),"",IFERROR(O16*$D16,0)+IFERROR(P16,0)) | Y16: =IF(AND(Q16="",R16=""),"",IFERROR(Q16*$D16,0)+IFERROR(R16,0))
A17: =Insumos!$A51 | B17: =Insumos!$B51 | C17: =Insumos!$E51 | D17: =Insumos!$F51 | S17: =IF(AND(E17="",F17=""),"",IFERROR(E17*$D17,0)+IFERROR(F17,0)) | T17: =IF(AND(G17="",H17=""),"",IFERROR(G17*$D17,0)+IFERROR(H17,0)) | U17: =IF(AND(I17="",J17=""),"",IFERROR(I17*$D17,0)+IFERROR(J17,0)) | V17: =IF(AND(K17="",L17=""),"",IFERROR(K17*$D17,0)+IFERROR(L17,0)) | W17: =IF(AND(M17="",N17=""),"",IFERROR(M17*$D17,0)+IFERROR(N17,0)) | X17: =IF(AND(O17="",P17=""),"",IFERROR(O17*$D17,0)+IFERROR(P17,0)) | Y17: =IF(AND(Q17="",R17=""),"",IFERROR(Q17*$D17,0)+IFERROR(R17,0))
A18: =Insumos!$A52 | B18: =Insumos!$B52 | C18: =Insumos!$E52 | D18: =Insumos!$F52 | S18: =IF(AND(E18="",F18=""),"",IFERROR(E18*$D18,0)+IFERROR(F18,0)) | T18: =IF(AND(G18="",H18=""),"",IFERROR(G18*$D18,0)+IFERROR(H18,0)) | U18: =IF(AND(I18="",J18=""),"",IFERROR(I18*$D18,0)+IFERROR(J18,0)) | V18: =IF(AND(K18="",L18=""),"",IFERROR(K18*$D18,0)+IFERROR(L18,0)) | W18: =IF(AND(M18="",N18=""),"",IFERROR(M18*$D18,0)+IFERROR(N18,0)) | X18: =IF(AND(O18="",P18=""),"",IFERROR(O18*$D18,0)+IFERROR(P18,0)) | Y18: =IF(AND(Q18="",R18=""),"",IFERROR(Q18*$D18,0)+IFERROR(R18,0))
A19: =Insumos!$A54 | B19: =Insumos!$B54 | C19: =Insumos!$E54 | D19: =Insumos!$F54 | S19: =IF(AND(E19="",F19=""),"",IFERROR(E19*$D19,0)+IFERROR(F19,0)) | T19: =IF(AND(G19="",H19=""),"",IFERROR(G19*$D19,0)+IFERROR(H19,0)) | U19: =IF(AND(I19="",J19=""),"",IFERROR(I19*$D19,0)+IFERROR(J19,0)) | V19: =IF(AND(K19="",L19=""),"",IFERROR(K19*$D19,0)+IFERROR(L19,0)) | W19: =IF(AND(M19="",N19=""),"",IFERROR(M19*$D19,0)+IFERROR(N19,0)) | X19: =IF(AND(O19="",P19=""),"",IFERROR(O19*$D19,0)+IFERROR(P19,0)) | Y19: =IF(AND(Q19="",R19=""),"",IFERROR(Q19*$D19,0)+IFERROR(R19,0))
A20: =Insumos!$A55 | B20: =Insumos!$B55 | C20: =Insumos!$E55 | D20: =Insumos!$F55 | S20: =IF(AND(E20="",F20=""),"",IFERROR(E20*$D20,0)+IFERROR(F20,0)) | T20: =IF(AND(G20="",H20=""),"",IFERROR(G20*$D20,0)+IFERROR(H20,0)) | U20: =IF(AND(I20="",J20=""),"",IFERROR(I20*$D20,0)+IFERROR(J20,0)) | V20: =IF(AND(K20="",L20=""),"",IFERROR(K20*$D20,0)+IFERROR(L20,0)) | W20: =IF(AND(M20="",N20=""),"",IFERROR(M20*$D20,0)+IFERROR(N20,0)) | X20: =IF(AND(O20="",P20=""),"",IFERROR(O20*$D20,0)+IFERROR(P20,0)) | Y20: =IF(AND(Q20="",R20=""),"",IFERROR(Q20*$D20,0)+IFERROR(R20,0))
A21: =Insumos!$A56 | B21: =Insumos!$B56 | C21: =Insumos!$E56 | D21: =Insumos!$F56 | S21: =IF(AND(E21="",F21=""),"",IFERROR(E21*$D21,0)+IFERROR(F21,0)) | T21: =IF(AND(G21="",H21=""),"",IFERROR(G21*$D21,0)+IFERROR(H21,0)) | U21: =IF(AND(I21="",J21=""),"",IFERROR(I21*$D21,0)+IFERROR(J21,0)) | V21: =IF(AND(K21="",L21=""),"",IFERROR(K21*$D21,0)+IFERROR(L21,0)) | W21: =IF(AND(M21="",N21=""),"",IFERROR(M21*$D21,0)+IFERROR(N21,0)) | X21: =IF(AND(O21="",P21=""),"",IFERROR(O21*$D21,0)+IFERROR(P21,0)) | Y21: =IF(AND(Q21="",R21=""),"",IFERROR(Q21*$D21,0)+IFERROR(R21,0))
A22: =Insumos!$A59 | B22: =Insumos!$B59 | C22: =Insumos!$E59 | D22: =Insumos!$F59 | S22: =IF(AND(E22="",F22=""),"",IFERROR(E22*$D22,0)+IFERROR(F22,0)) | T22: =IF(AND(G22="",H22=""),"",IFERROR(G22*$D22,0)+IFERROR(H22,0)) | U22: =IF(AND(I22="",J22=""),"",IFERROR(I22*$D22,0)+IFERROR(J22,0)) | V22: =IF(AND(K22="",L22=""),"",IFERROR(K22*$D22,0)+IFERROR(L22,0)) | W22: =IF(AND(M22="",N22=""),"",IFERROR(M22*$D22,0)+IFERROR(N22,0)) | X22: =IF(AND(O22="",P22=""),"",IFERROR(O22*$D22,0)+IFERROR(P22,0)) | Y22: =IF(AND(Q22="",R22=""),"",IFERROR(Q22*$D22,0)+IFERROR(R22,0))
A23: =Insumos!$A60 | B23: =Insumos!$B60 | C23: =Insumos!$E60 | D23: =Insumos!$F60 | S23: =IF(AND(E23="",F23=""),"",IFERROR(E23*$D23,0)+IFERROR(F23,0)) | T23: =IF(AND(G23="",H23=""),"",IFERROR(G23*$D23,0)+IFERROR(H23,0)) | U23: =IF(AND(I23="",J23=""),"",IFERROR(I23*$D23,0)+IFERROR(J23,0)) | V23: =IF(AND(K23="",L23=""),"",IFERROR(K23*$D23,0)+IFERROR(L23,0)) | W23: =IF(AND(M23="",N23=""),"",IFERROR(M23*$D23,0)+IFERROR(N23,0)) | X23: =IF(AND(O23="",P23=""),"",IFERROR(O23*$D23,0)+IFERROR(P23,0)) | Y23: =IF(AND(Q23="",R23=""),"",IFERROR(Q23*$D23,0)+IFERROR(R23,0))
A24: =Insumos!$A62 | B24: =Insumos!$B62 | C24: =Insumos!$E62 | D24: =Insumos!$F62 | S24: =IF(AND(E24="",F24=""),"",IFERROR(E24*$D24,0)+IFERROR(F24,0)) | T24: =IF(AND(G24="",H24=""),"",IFERROR(G24*$D24,0)+IFERROR(H24,0)) | U24: =IF(AND(I24="",J24=""),"",IFERROR(I24*$D24,0)+IFERROR(J24,0)) | V24: =IF(AND(K24="",L24=""),"",IFERROR(K24*$D24,0)+IFERROR(L24,0)) | W24: =IF(AND(M24="",N24=""),"",IFERROR(M24*$D24,0)+IFERROR(N24,0)) | X24: =IF(AND(O24="",P24=""),"",IFERROR(O24*$D24,0)+IFERROR(P24,0)) | Y24: =IF(AND(Q24="",R24=""),"",IFERROR(Q24*$D24,0)+IFERROR(R24,0))
A25: =Insumos!$A69 | B25: =Insumos!$B69 | C25: =Insumos!$E69 | D25: =Insumos!$F69 | S25: =IF(AND(E25="",F25=""),"",IFERROR(E25*$D25,0)+IFERROR(F25,0)) | T25: =IF(AND(G25="",H25=""),"",IFERROR(G25*$D25,0)+IFERROR(H25,0)) | U25: =IF(AND(I25="",J25=""),"",IFERROR(I25*$D25,0)+IFERROR(J25,0)) | V25: =IF(AND(K25="",L25=""),"",IFERROR(K25*$D25,0)+IFERROR(L25,0)) | W25: =IF(AND(M25="",N25=""),"",IFERROR(M25*$D25,0)+IFERROR(N25,0)) | X25: =IF(AND(O25="",P25=""),"",IFERROR(O25*$D25,0)+IFERROR(P25,0)) | Y25: =IF(AND(Q25="",R25=""),"",IFERROR(Q25*$D25,0)+IFERROR(R25,0))
A26: =Insumos!$A72 | B26: =Insumos!$B72 | C26: =Insumos!$E72 | D26: =Insumos!$F72 | S26: =IF(AND(E26="",F26=""),"",IFERROR(E26*$D26,0)+IFERROR(F26,0)) | T26: =IF(AND(G26="",H26=""),"",IFERROR(G26*$D26,0)+IFERROR(H26,0)) | U26: =IF(AND(I26="",J26=""),"",IFERROR(I26*$D26,0)+IFERROR(J26,0)) | V26: =IF(AND(K26="",L26=""),"",IFERROR(K26*$D26,0)+IFERROR(L26,0)) | W26: =IF(AND(M26="",N26=""),"",IFERROR(M26*$D26,0)+IFERROR(N26,0)) | X26: =IF(AND(O26="",P26=""),"",IFERROR(O26*$D26,0)+IFERROR(P26,0)) | Y26: =IF(AND(Q26="",R26=""),"",IFERROR(Q26*$D26,0)+IFERROR(R26,0))
A27: =Insumos!$A73 | B27: =Insumos!$B73 | C27: =Insumos!$E73 | D27: =Insumos!$F73 | S27: =IF(AND(E27="",F27=""),"",IFERROR(E27*$D27,0)+IFERROR(F27,0)) | T27: =IF(AND(G27="",H27=""),"",IFERROR(G27*$D27,0)+IFERROR(H27,0)) | U27: =IF(AND(I27="",J27=""),"",IFERROR(I27*$D27,0)+IFERROR(J27,0)) | V27: =IF(AND(K27="",L27=""),"",IFERROR(K27*$D27,0)+IFERROR(L27,0)) | W27: =IF(AND(M27="",N27=""),"",IFERROR(M27*$D27,0)+IFERROR(N27,0)) | X27: =IF(AND(O27="",P27=""),"",IFERROR(O27*$D27,0)+IFERROR(P27,0)) | Y27: =IF(AND(Q27="",R27=""),"",IFERROR(Q27*$D27,0)+IFERROR(R27,0))
A28: =Insumos!$A74 | B28: =Insumos!$B74 | C28: =Insumos!$E74 | D28: =Insumos!$F74 | S28: =IF(AND(E28="",F28=""),"",IFERROR(E28*$D28,0)+IFERROR(F28,0)) | T28: =IF(AND(G28="",H28=""),"",IFERROR(G28*$D28,0)+IFERROR(H28,0)) | U28: =IF(AND(I28="",J28=""),"",IFERROR(I28*$D28,0)+IFERROR(J28,0)) | V28: =IF(AND(K28="",L28=""),"",IFERROR(K28*$D28,0)+IFERROR(L28,0)) | W28: =IF(AND(M28="",N28=""),"",IFERROR(M28*$D28,0)+IFERROR(N28,0)) | X28: =IF(AND(O28="",P28=""),"",IFERROR(O28*$D28,0)+IFERROR(P28,0)) | Y28: =IF(AND(Q28="",R28=""),"",IFERROR(Q28*$D28,0)+IFERROR(R28,0))
A29: =Insumos!$A78 | B29: =Insumos!$B78 | C29: =Insumos!$E78 | D29: =Insumos!$F78 | S29: =IF(AND(E29="",F29=""),"",IFERROR(E29*$D29,0)+IFERROR(F29,0)) | T29: =IF(AND(G29="",H29=""),"",IFERROR(G29*$D29,0)+IFERROR(H29,0)) | U29: =IF(AND(I29="",J29=""),"",IFERROR(I29*$D29,0)+IFERROR(J29,0)) | V29: =IF(AND(K29="",L29=""),"",IFERROR(K29*$D29,0)+IFERROR(L29,0)) | W29: =IF(AND(M29="",N29=""),"",IFERROR(M29*$D29,0)+IFERROR(N29,0)) | X29: =IF(AND(O29="",P29=""),"",IFERROR(O29*$D29,0)+IFERROR(P29,0)) | Y29: =IF(AND(Q29="",R29=""),"",IFERROR(Q29*$D29,0)+IFERROR(R29,0))
A30: =Insumos!$A79 | B30: =Insumos!$B79 | C30: =Insumos!$E79 | D30: =Insumos!$F79 | S30: =IF(AND(E30="",F30=""),"",IFERROR(E30*$D30,0)+IFERROR(F30,0)) | T30: =IF(AND(G30="",H30=""),"",IFERROR(G30*$D30,0)+IFERROR(H30,0)) | U30: =IF(AND(I30="",J30=""),"",IFERROR(I30*$D30,0)+IFERROR(J30,0)) | V30: =IF(AND(K30="",L30=""),"",IFERROR(K30*$D30,0)+IFERROR(L30,0)) | W30: =IF(AND(M30="",N30=""),"",IFERROR(M30*$D30,0)+IFERROR(N30,0)) | X30: =IF(AND(O30="",P30=""),"",IFERROR(O30*$D30,0)+IFERROR(P30,0)) | Y30: =IF(AND(Q30="",R30=""),"",IFERROR(Q30*$D30,0)+IFERROR(R30,0))
A31: =Insumos!$A80 | B31: =Insumos!$B80 | C31: =Insumos!$E80 | D31: =Insumos!$F80 | S31: =IF(AND(E31="",F31=""),"",IFERROR(E31*$D31,0)+IFERROR(F31,0)) | T31: =IF(AND(G31="",H31=""),"",IFERROR(G31*$D31,0)+IFERROR(H31,0)) | U31: =IF(AND(I31="",J31=""),"",IFERROR(I31*$D31,0)+IFERROR(J31,0)) | V31: =IF(AND(K31="",L31=""),"",IFERROR(K31*$D31,0)+IFERROR(L31,0)) | W31: =IF(AND(M31="",N31=""),"",IFERROR(M31*$D31,0)+IFERROR(N31,0)) | X31: =IF(AND(O31="",P31=""),"",IFERROR(O31*$D31,0)+IFERROR(P31,0)) | Y31: =IF(AND(Q31="",R31=""),"",IFERROR(Q31*$D31,0)+IFERROR(R31,0))
A32: =Insumos!$A81 | B32: =Insumos!$B81 | C32: =Insumos!$E81 | D32: =Insumos!$F81 | S32: =IF(AND(E32="",F32=""),"",IFERROR(E32*$D32,0)+IFERROR(F32,0)) | T32: =IF(AND(G32="",H32=""),"",IFERROR(G32*$D32,0)+IFERROR(H32,0)) | U32: =IF(AND(I32="",J32=""),"",IFERROR(I32*$D32,0)+IFERROR(J32,0)) | V32: =IF(AND(K32="",L32=""),"",IFERROR(K32*$D32,0)+IFERROR(L32,0)) | W32: =IF(AND(M32="",N32=""),"",IFERROR(M32*$D32,0)+IFERROR(N32,0)) | X32: =IF(AND(O32="",P32=""),"",IFERROR(O32*$D32,0)+IFERROR(P32,0)) | Y32: =IF(AND(Q32="",R32=""),"",IFERROR(Q32*$D32,0)+IFERROR(R32,0))
A33: =Insumos!$A92 | B33: =Insumos!$B92 | C33: =Insumos!$E92 | D33: =Insumos!$F92 | S33: =IF(AND(E33="",F33=""),"",IFERROR(E33*$D33,0)+IFERROR(F33,0)) | T33: =IF(AND(G33="",H33=""),"",IFERROR(G33*$D33,0)+IFERROR(H33,0)) | U33: =IF(AND(I33="",J33=""),"",IFERROR(I33*$D33,0)+IFERROR(J33,0)) | V33: =IF(AND(K33="",L33=""),"",IFERROR(K33*$D33,0)+IFERROR(L33,0)) | W33: =IF(AND(M33="",N33=""),"",IFERROR(M33*$D33,0)+IFERROR(N33,0)) | X33: =IF(AND(O33="",P33=""),"",IFERROR(O33*$D33,0)+IFERROR(P33,0)) | Y33: =IF(AND(Q33="",R33=""),"",IFERROR(Q33*$D33,0)+IFERROR(R33,0))
A34: =Insumos!$A93 | B34: =Insumos!$B93 | C34: =Insumos!$E93 | D34: =Insumos!$F93 | S34: =IF(AND(E34="",F34=""),"",IFERROR(E34*$D34,0)+IFERROR(F34,0)) | T34: =IF(AND(G34="",H34=""),"",IFERROR(G34*$D34,0)+IFERROR(H34,0)) | U34: =IF(AND(I34="",J34=""),"",IFERROR(I34*$D34,0)+IFERROR(J34,0)) | V34: =IF(AND(K34="",L34=""),"",IFERROR(K34*$D34,0)+IFERROR(L34,0)) | W34: =IF(AND(M34="",N34=""),"",IFERROR(M34*$D34,0)+IFERROR(N34,0)) | X34: =IF(AND(O34="",P34=""),"",IFERROR(O34*$D34,0)+IFERROR(P34,0)) | Y34: =IF(AND(Q34="",R34=""),"",IFERROR(Q34*$D34,0)+IFERROR(R34,0))
A35: =Insumos!$A96 | B35: =Insumos!$B96 | C35: =Insumos!$E96 | D35: =Insumos!$F96 | S35: =IF(AND(E35="",F35=""),"",IFERROR(E35*$D35,0)+IFERROR(F35,0)) | T35: =IF(AND(G35="",H35=""),"",IFERROR(G35*$D35,0)+IFERROR(H35,0)) | U35: =IF(AND(I35="",J35=""),"",IFERROR(I35*$D35,0)+IFERROR(J35,0)) | V35: =IF(AND(K35="",L35=""),"",IFERROR(K35*$D35,0)+IFERROR(L35,0)) | W35: =IF(AND(M35="",N35=""),"",IFERROR(M35*$D35,0)+IFERROR(N35,0)) | X35: =IF(AND(O35="",P35=""),"",IFERROR(O35*$D35,0)+IFERROR(P35,0)) | Y35: =IF(AND(Q35="",R35=""),"",IFERROR(Q35*$D35,0)+IFERROR(R35,0))
A36: =Insumos!$A97 | B36: =Insumos!$B97 | C36: =Insumos!$E97 | D36: =Insumos!$F97 | S36: =IF(AND(E36="",F36=""),"",IFERROR(E36*$D36,0)+IFERROR(F36,0)) | T36: =IF(AND(G36="",H36=""),"",IFERROR(G36*$D36,0)+IFERROR(H36,0)) | U36: =IF(AND(I36="",J36=""),"",IFERROR(I36*$D36,0)+IFERROR(J36,0)) | V36: =IF(AND(K36="",L36=""),"",IFERROR(K36*$D36,0)+IFERROR(L36,0)) | W36: =IF(AND(M36="",N36=""),"",IFERROR(M36*$D36,0)+IFERROR(N36,0)) | X36: =IF(AND(O36="",P36=""),"",IFERROR(O36*$D36,0)+IFERROR(P36,0)) | Y36: =IF(AND(Q36="",R36=""),"",IFERROR(Q36*$D36,0)+IFERROR(R36,0))
A37: =Insumos!$A98 | B37: =Insumos!$B98 | C37: =Insumos!$E98 | D37: =Insumos!$F98 | S37: =IF(AND(E37="",F37=""),"",IFERROR(E37*$D37,0)+IFERROR(F37,0)) | T37: =IF(AND(G37="",H37=""),"",IFERROR(G37*$D37,0)+IFERROR(H37,0)) | U37: =IF(AND(I37="",J37=""),"",IFERROR(I37*$D37,0)+IFERROR(J37,0)) | V37: =IF(AND(K37="",L37=""),"",IFERROR(K37*$D37,0)+IFERROR(L37,0)) | W37: =IF(AND(M37="",N37=""),"",IFERROR(M37*$D37,0)+IFERROR(N37,0)) | X37: =IF(AND(O37="",P37=""),"",IFERROR(O37*$D37,0)+IFERROR(P37,0)) | Y37: =IF(AND(Q37="",R37=""),"",IFERROR(Q37*$D37,0)+IFERROR(R37,0))
A38: =Insumos!$A99 | B38: =Insumos!$B99 | C38: =Insumos!$E99 | D38: =Insumos!$F99 | S38: =IF(AND(E38="",F38=""),"",IFERROR(E38*$D38,0)+IFERROR(F38,0)) | T38: =IF(AND(G38="",H38=""),"",IFERROR(G38*$D38,0)+IFERROR(H38,0)) | U38: =IF(AND(I38="",J38=""),"",IFERROR(I38*$D38,0)+IFERROR(J38,0)) | V38: =IF(AND(K38="",L38=""),"",IFERROR(K38*$D38,0)+IFERROR(L38,0)) | W38: =IF(AND(M38="",N38=""),"",IFERROR(M38*$D38,0)+IFERROR(N38,0)) | X38: =IF(AND(O38="",P38=""),"",IFERROR(O38*$D38,0)+IFERROR(P38,0)) | Y38: =IF(AND(Q38="",R38=""),"",IFERROR(Q38*$D38,0)+IFERROR(R38,0))
A39: =Insumos!$A100 | B39: =Insumos!$B100 | C39: =Insumos!$E100 | D39: =Insumos!$F100 | S39: =IF(AND(E39="",F39=""),"",IFERROR(E39*$D39,0)+IFERROR(F39,0)) | T39: =IF(AND(G39="",H39=""),"",IFERROR(G39*$D39,0)+IFERROR(H39,0)) | U39: =IF(AND(I39="",J39=""),"",IFERROR(I39*$D39,0)+IFERROR(J39,0)) | V39: =IF(AND(K39="",L39=""),"",IFERROR(K39*$D39,0)+IFERROR(L39,0)) | W39: =IF(AND(M39="",N39=""),"",IFERROR(M39*$D39,0)+IFERROR(N39,0)) | X39: =IF(AND(O39="",P39=""),"",IFERROR(O39*$D39,0)+IFERROR(P39,0)) | Y39: =IF(AND(Q39="",R39=""),"",IFERROR(Q39*$D39,0)+IFERROR(R39,0))
A40: =Insumos!$A102 | B40: =Insumos!$B102 | C40: =Insumos!$E102 | D40: =Insumos!$F102 | S40: =IF(AND(E40="",F40=""),"",IFERROR(E40*$D40,0)+IFERROR(F40,0)) | T40: =IF(AND(G40="",H40=""),"",IFERROR(G40*$D40,0)+IFERROR(H40,0)) | U40: =IF(AND(I40="",J40=""),"",IFERROR(I40*$D40,0)+IFERROR(J40,0)) | V40: =IF(AND(K40="",L40=""),"",IFERROR(K40*$D40,0)+IFERROR(L40,0)) | W40: =IF(AND(M40="",N40=""),"",IFERROR(M40*$D40,0)+IFERROR(N40,0)) | X40: =IF(AND(O40="",P40=""),"",IFERROR(O40*$D40,0)+IFERROR(P40,0)) | Y40: =IF(AND(Q40="",R40=""),"",IFERROR(Q40*$D40,0)+IFERROR(R40,0))
...

Sheet 4 Prod Panaderia
A1: PLANILLA 4 · PRODUCCION DIARIA — PANADERÍA
A2: Jefe de area: ____________________ Semana: ____/____ al ____/____ Se elabora en: Central
A3: ELABORADO = lo que salio bueno. DESCARTE = lo que se quemo, salio mal, se cayo o se tiro. El detalle del motivo de cada descarte va en la planilla 5.
A4: PRODUCTO | B4: UNID. | C4: =IF(Config!$B$10="","LUNES",UPPER("LUN")&" "&TEXT(Config!$B$10,"dd/mm")) | E4: =IF(Config!$B$11="","MARTES",UPPER("MAR")&" "&TEXT(Config!$B$11,"dd/mm")) | G4: =IF(Config!$B$12="","MIERCOLES",UPPER("MIE")&" "&TEXT(Config!$B$12,"dd/mm")) | I4: =IF(Config!$B$13="","JUEVES",UPPER("JUE")&" "&TEXT(Config!$B$13,"dd/mm")) | K4: =IF(Config!$B$14="","VIERNES",UPPER("VIE")&" "&TEXT(Config!$B$14,"dd/mm")) | M4: =IF(Config!$B$15="","SABADO",UPPER("SAB")&" "&TEXT(Config!$B$15,"dd/mm")) | O4: =IF(Config!$B$16="","DOMINGO",UPPER("DOM")&" "&TEXT(Config!$B$16,"dd/mm")) | Q4: TOTAL ELABORADO | R4: TOTAL DESCARTE | S4: % DESC.
C5: ELABOR. | D5: DESCAR. | E5: ELABOR. | F5: DESCAR. | G5: ELABOR. | H5: DESCAR. | I5: ELABOR. | J5: DESCAR. | K5: ELABOR. | L5: DESCAR. | M5: ELABOR. | N5: DESCAR. | O5: ELABOR. | P5: DESCAR.
A6: Bagel | B6: u | Q6: =SUM(C6,E6,G6,I6,K6,M6,O6) | R6: =SUM(D6,F6,H6,J6,L6,N6,P6) | S6: =IF($Q6=0,"",$R6/$Q6)
A7: Bizcochos | B7: kg | Q7: =SUM(C7,E7,G7,I7,K7,M7,O7) | R7: =SUM(D7,F7,H7,J7,L7,N7,P7) | S7: =IF($Q7=0,"",$R7/$Q7)
A8: Bizcochos de margarina | B8: kg | Q8: =SUM(C8,E8,G8,I8,K8,M8,O8) | R8: =SUM(D8,F8,H8,J8,L8,N8,P8) | S8: =IF($Q8=0,"",$R8/$Q8)
A9: Bizcochos redondos | B9: kg | Q9: =SUM(C9,E9,G9,I9,K9,M9,O9) | R9: =SUM(D9,F9,H9,J9,L9,N9,P9) | S9: =IF($Q9=0,"",$R9/$Q9)
A10: Bollitos B/N | B10: u | Q10: =SUM(C10,E10,G10,I10,K10,M10,O10) | R10: =SUM(D10,F10,H10,J10,L10,N10,P10) | S10: =IF($Q10=0,"",$R10/$Q10)
A11: Bollos grandes | B11: u | Q11: =SUM(C11,E11,G11,I11,K11,M11,O11) | R11: =SUM(D11,F11,H11,J11,L11,N11,P11) | S11: =IF($Q11=0,"",$R11/$Q11)
A12: Caseras | B12: u | Q12: =SUM(C12,E12,G12,I12,K12,M12,O12) | R12: =SUM(D12,F12,H12,J12,L12,N12,P12) | S12: =IF($Q12=0,"",$R12/$Q12)
A13: Caseritas | B13: u | Q13: =SUM(C13,E13,G13,I13,K13,M13,O13) | R13: =SUM(D13,F13,H13,J13,L13,N13,P13) | S13: =IF($Q13=0,"",$R13/$Q13)
A14: Chatas | B14: kg | Q14: =SUM(C14,E14,G14,I14,K14,M14,O14) | R14: =SUM(D14,F14,H14,J14,L14,N14,P14) | S14: =IF($Q14=0,"",$R14/$Q14)
A15: Cremona | B15: u | Q15: =SUM(C15,E15,G15,I15,K15,M15,O15) | R15: =SUM(D15,F15,H15,J15,L15,N15,P15) | S15: =IF($Q15=0,"",$R15/$Q15)
A16: Focaccia | B16: u | Q16: =SUM(C16,E16,G16,I16,K16,M16,O16) | R16: =SUM(D16,F16,H16,J16,L16,N16,P16) | S16: =IF($Q16=0,"",$R16/$Q16)
A17: Libritos | B17: u | Q17: =SUM(C17,E17,G17,I17,K17,M17,O17) | R17: =SUM(D17,F17,H17,J17,L17,N17,P17) | S17: =IF($Q17=0,"",$R17/$Q17)
... A47: TT Tortillas | B47: u | Q47: =SUM(C47,E47,G47,I47,K47,M47,O47) | R47: =SUM(D47,F47,H47,J47,L47,N47,P47) | S47: =IF($Q47=0,"",$R47/$Q47)
Q48: =SUM(C48,E48,G48,I48,K48,M48,O48) | R48: =SUM(D48,F48,H48,J48,L48,N48,P48) | S48: =IF($Q48=0,"",$R48/$Q48)
Q49: =SUM(C49,E49,G49,I49,K49,M49,O49) | R49: =SUM(D49,F49,H49,J49,L49,N49,P49) | S49: =IF($Q49=0,"",$R49/$Q49)
Q50: =SUM(C50,E50,G50,I50,K50,M50,O50) | R50: =SUM(D50,F50,H50,J50,L50,N50,P50) | S50: =IF($Q50=0,"",$R50/$Q50)
Q51: =SUM(C51,E51,G51,I51,K51,M51,O51) | R51: =SUM(D51,F51,H51,J51,L51,N51,P51) | S51: =IF($Q51=0,"",$R51/$Q51)
Q52: =SUM(C52,E52,G52,I52,K52,M52,O52) | R52: =SUM(D52,F52,H52,J52,L52,N52,P52) | S52: =IF($Q52=0,"",$R52/$Q52)
Q53: =SUM(C53,E53,G53,I53,K53,M53,O53) | R53: =SUM(D53,F53,H53,J53,L53,N53,P53) | S53: =IF($Q53=0,"",$R53/$Q53)
Q54: =SUM(C54,E54,G54,I54,K54,M54,O54) | R54: =SUM(D54,F54,H54,J54,L54,N54,P54) | S54: =IF($Q54=0,"",$R54/$Q54)
Q55: =SUM(C55,E55,G55,I55,K55,M55,O55) | R55: =SUM(D55,F55,H55,J55,L55,N55,P55) | S55: =IF($Q55=0,"",$R55/$Q55)
A56: TOTALES DEL AREA | C56: =SUM(C6:C55) | D56: =SUM(D6:D55) | E56: =SUM(E6:E55) | F56: =SUM(F6:F55) | G56: =SUM(G6:G55) | H56: =SUM(H6:H55) | I56: =SUM(I6:I55) | J56: =SUM(J6:J55) | ... R56: =SUM(R6:R55) | S56: =IF($Q56=0,"",$R56/$Q56)

Sheet 4 Prod Pasteleria
A1: PLANILLA 4 · PRODUCCION DIARIA — PASTELERÍA
A2: Jefe de area: ____________________ Semana: ____/____ al ____/____ Se elabora en: Central
A3: ELABORADO = lo que salio bueno. DESCARTE = lo que se quemo, salio mal, se cayo o se tiro. El detalle del motivo de cada descarte va en la planilla 5.
A4: PRODUCTO | B4: UNID. | C4: =IF(Config!$B$10="","LUNES",UPPER("LUN")&" "&TEXT(Config!$B$10,"dd/mm")) | E4: =IF(Config!$B$11="","MARTES",UPPER("MAR")&" "&TEXT(Config!$B$11,"dd/mm")) | G4: =IF(Config!$B$12="","MIERCOLES",UPPER("MIE")&" "&TEXT(Config!$B$12,"dd/mm")) | I4: =IF(Config!$B$13="","JUEVES",UPPER("JUE")&" "&TEXT(Config!$B$13,"dd/mm")) | K4: =IF(Config!$B$14="","VIERNES",UPPER("VIE")&" "&TEXT(Config!$B$14,"dd/mm")) | M4: =IF(Config!$B$15="","SABADO",UPPER("SAB")&" "&TEXT(Config!$B$15,"dd/mm")) | O4: =IF(Config!$B$16="","DOMINGO",UPPER("DOM")&" "&TEXT(Config!$B$16,"dd/mm")) | Q4: TOTAL ELABORADO | R4: TOTAL DESCARTE | S4: % DESC.
C5: ELABOR. | D5: DESCAR. | E5: ELABOR. | F5: DESCAR. | G5: ELABOR. | H5: DESCAR. | I5: ELABOR. | J5: DESCAR. | K5: ELABOR. | L5: DESCAR. | M5: ELABOR. | N5: DESCAR. | O5: ELABOR. | P5: DESCAR.
A6: Alemana | B6: u | Q6: =SUM(C6,E6,G6,I6,K6,M6,O6) | R6: =SUM(D6,F6,H6,J6,L6,N6,P6) | S6: =IF($Q6=0,"",$R6/$Q6)
A7: Bariloche | B7: u | Q7: =SUM(C7,E7,G7,I7,K7,M7,O7) | R7: =SUM(D7,F7,H7,J7,L7,N7,P7) | S7: =IF($Q7=0,"",$R7/$Q7)
A8: Cabsha | B8: u | Q8: =SUM(C8,E8,G8,I8,K8,M8,O8) | R8: =SUM(D8,F8,H8,J8,L8,N8,P8) | S8: =IF($Q8=0,"",$R8/$Q8)
A9: Cheesecake frutos rojos | B9: u | Q9: =SUM(C9,E9,G9,I9,K9,M9,O9) | R9: =SUM(D9,F9,H9,J9,L9,N9,P9) | S9: =IF($Q9=0,"",$R9/$Q9)
A10: Cheesecake maracuyá | B10: u | Q10: =SUM(C10,E10,G10,I10,K10,M10,O10) | R10: =SUM(D10,F10,H10,J10,L10,N10,P10) | S10: =IF($Q10=0,"",$R10/$Q10)
A11: Cheesecake NY cocido | B11: u | Q11: =SUM(C11,E11,G11,I11,K11,M11,O11) | R11: =SUM(D11,F11,H11,J11,L11,N11,P11) | S11: =IF($Q11=0,"",$R11/$Q11)
A12: Chocotorta | B12: u | Q12: =SUM(C12,E12,G12,I12,K12,M12,O12) | R12: =SUM(D12,F12,H12,J12,L12,N12,P12) | S12: =IF($Q12=0,"",$R12/$Q12)
A13: Delicia con chocolates | B13: u | Q13: =SUM(C13,E13,G13,I13,K13,M13,O13) | R13: =SUM(D13,F13,H13,J13,L13,N13,P13) | S13: =IF($Q13=0,"",$R13/$Q13)
A14: Delicia con frutas | B14: u | Q14: =SUM(C14,E14,G14,I14,K14,M14,O14) | R14: =SUM(D14,F14,H14,J14,L14,N14,P14) | S14: =IF($Q14=0,"",$R14/$Q14)
A15: Lemon Pie | B15: u | Q15: =SUM(C15,E15,G15,I15,K15,M15,O15) | R15: =SUM(D15,F15,H15,J15,L15,N15,P15) | S15: =IF($Q15=0,"",$R15/$Q15)
A16: Marquise | B16: u | Q16: =SUM(C16,E16,G16,I16,K16,M16,O16) | R16: =SUM(D16,F16,H16,J16,L16,N16,P16) | S16: =IF($Q16=0,"",$R16/$Q16)
A17: Mini Cabsha | B17: u | Q17: =SUM(C17,E17,G17,I17,K17,M17,O17) | R17: =SUM(D17,F17,H17,J17,L17,N17,P17) | S17: =IF($Q17=0,"",$R17/$Q17)
... A43: Turrón Salteño | B43: u | Q43: =SUM(C43,E43,G43,I43,K43,M43,O43) | R43: =SUM(D43,F43,H43,J43,L43,N43,P43) | S43: =IF($Q43=0,"",$R43/$Q43)
Q44: =SUM(C44,E44,G44,I44,K44,M44,O44) | R44: =SUM(D44,F44,H44,J44,L44,N44,P44) | S44: =IF($Q44=0,"",$R44/$Q44)
Q45: =SUM(C45,E45,G45,I45,K45,M45,O45) | R45: =SUM(D45,F45,H45,J45,L45,N45,P45) | S45: =IF($Q45=0,"",$R45/$Q45)
Q46: =SUM(C46,E46,G46,I46,K46,M46,O46) | R46: =SUM(D46,F46,H46,J46,L46,N46,P46) | S46: =IF($Q46=0,"",$R46/$Q46)
Q47: =SUM(C47,E47,G47,I47,K47,M47,O47) | R47: =SUM(D47,F47,H47,J47,L47,N47,P47) | S47: =IF($Q47=0,"",$R47/$Q47)
Q48: =SUM(C48,E48,G48,I48,K48,M48,O48) | R48: =SUM(D48,F48,H48,J48,L48,N48,P48) | S48: =IF($Q48=0,"",$R48/$Q48)
Q49: =SUM(C49,E49,G49,I49,K49,M49,O49) | R49: =SUM(D49,F49,H49,J49,L49,N49,P49) | S49: =IF($Q49=0,"",$R49/$Q49)
Q50: =SUM(C50,E50,G50,I50,K50,M50,O50) | R50: =SUM(D50,F50,H50,J50,L50,N50,P50) | S50: =IF($Q50=0,"",$R50/$Q50)
Q51: =SUM(C51,E51,G51,I51,K51,M51,O51) | R51: =SUM(D51,F51,H51,J51,L51,N51,P51) | S51: =IF($Q51=0,"",$R51/$Q51)
A52: TOTALES DEL AREA | C52: =SUM(C6:C51) | D52: =SUM(D6:D51) | E52: =SUM(E6:E51) | F52: =SUM(F6:F51) | G52: =SUM(G6:G51) | H52: =SUM(H6:H51) | I52: =SUM(I6:I51) | J52: =SUM(J6:J51) | ... R52: =SUM(R6:R51) | S52: =IF($Q52=0,"",$R52/$Q52)

Sheet 4 Prod Especialidades
A1: PLANILLA 4 · PRODUCCION DIARIA — ESPECIALIDADES
A2: Jefe de area: ____________________ Semana: ____/____ al ____/____ Se elabora en: Central
A3: ELABORADO = lo que salio bueno. DESCARTE = lo que se quemo, salio mal, se cayo o se tiro. El detalle del motivo de cada descarte va en la planilla 5.
A4: PRODUCTO | B4: UNID. | C4: =IF(Config!$B$10="","LUNES",UPPER("LUN")&" "&TEXT(Config!$B$10,"dd/mm")) | E4: =IF(Config!$B$11="","MARTES",UPPER("MAR")&" "&TEXT(Config!$B$11,"dd/mm")) | G4: =IF(Config!$B$12="","MIERCOLES",UPPER("MIE")&" "&TEXT(Config!$B$12,"dd/mm")) | I4: =IF(Config!$B$13="","JUEVES",UPPER("JUE")&" "&TEXT(Config!$B$13,"dd/mm")) | K4: =IF(Config!$B$14="","VIERNES",UPPER("VIE")&" "&TEXT(Config!$B$14,"dd/mm")) | M4: =IF(Config!$B$15="","SABADO",UPPER("SAB")&" "&TEXT(Config!$B$15,"dd/mm")) | O4: =IF(Config!$B$16="","DOMINGO",UPPER("DOM")&" "&TEXT(Config!$B$16,"dd/mm")) | Q4: TOTAL ELABORADO | R4: TOTAL DESCARTE | S4: % DESC.
C5: ELABOR. | D5: DESCAR. | E5: ELABOR. | F5: DESCAR. | G5: ELABOR. | H5: DESCAR. | I5: ELABOR. | J5: DESCAR. | K5: ELABOR. | L5: DESCAR. | M5: ELABOR. | N5: DESCAR. | O5: ELABOR. | P5: DESCAR.
A6: Alfajores choco blanco | B6: u | Q6: =SUM(C6,E6,G6,I6,K6,M6,O6) | R6: =SUM(D6,F6,H6,J6,L6,N6,P6) | S6: =IF($Q6=0,"",$R6/$Q6)
A7: Alfajores choco negro | B7: u | Q7: =SUM(C7,E7,G7,I7,K7,M7,O7) | R7: =SUM(D7,F7,H7,J7,L7,N7,P7) | S7: =IF($Q7=0,"",$R7/$Q7)
A8: Alfajores choco negro grande | B8: u | Q8: =SUM(C8,E8,G8,I8,K8,M8,O8) | R8: =SUM(D8,F8,H8,J8,L8,N8,P8) | S8: =IF($Q8=0,"",$R8/$Q8)
A9: Alfajores impalpable | B9: u | Q9: =SUM(C9,E9,G9,I9,K9,M9,O9) | R9: =SUM(D9,F9,H9,J9,L9,N9,P9) | S9: =IF($Q9=0,"",$R9/$Q9)
A10: Boulévant | B10: u | Q10: =SUM(C10,E10,G10,I10,K10,M10,O10) | R10: =SUM(D10,F10,H10,J10,L10,N10,P10) | S10: =IF($Q10=0,"",$R10/$Q10)
A11: Budín x kg naranja y amapola | B11: kg | Q11: =SUM(C11,E11,G11,I11,K11,M11,O11) | R11: =SUM(D11,F11,H11,J11,L11,N11,P11) | S11: =IF($Q11=0,"",$R11/$Q11)
A12: Budín x kg nuez y dulce | B12: kg | Q12: =SUM(C12,E12,G12,I12,K12,M12,O12) | R12: =SUM(D12,F12,H12,J12,L12,N12,P12) | S12: =IF($Q12=0,"",$R12/$Q12)
A13: Budín x unidad chico | B13: u | Q13: =SUM(C13,E13,G13,I13,K13,M13,O13) | R13: =SUM(D13,F13,H13,J13,L13,N13,P13) | S13: =IF($Q13=0,"",$R13/$Q13)
A14: Cañoncitos | B14: u | Q14: =SUM(C14,E14,G14,I14,K14,M14,O14) | R14: =SUM(D14,F14,H14,J14,L14,N14,P14) | S14: =IF($Q14=0,"",$R14/$Q14)
A15: Carasucias | B15: u | Q15: =SUM(C15,E15,G15,I15,K15,M15,O15) | R15: =SUM(D15,F15,H15,J15,L15,N15,P15) | S15: =IF($Q15=0,"",$R15/$Q15)
A16: Chipa | B16: u | Q16: =SUM(C16,E16,G16,I16,K16,M16,O16) | R16: =SUM(D16,F16,H16,J16,L16,N16,P16) | S16: =IF($Q16=0,"",$R16/$Q16)
A17: Chipa crudo bandeja x30 | B17: u | Q17: =SUM(C17,E17,G17,I17,K17,M17,O17) | R17: =SUM(D17,F17,H17,J17,L17,N17,P17) | S17: =IF($Q17=0,"",$R17/$Q17)
... A41: Torta x porción | B41: u | Q41: =SUM(C41,E41,G41,I41,K41,M41,O41) | R41: =SUM(D41,F41,H41,J41,L41,N41,P41) | S41: =IF($Q41=0,"",$R41/$Q41)
Q42: =SUM(C42,E42,G42,I42,K42,M42,O42) | R42: =SUM(D42,F42,H42,J42,L42,N42,P42) | S42: =IF($Q42=0,"",$R42/$Q42)
Q43: =SUM(C43,E43,G43,I43,K43,M43,O43) | R43: =SUM(D43,F43,H43,J43,L43,N43,P43) | S43: =IF($Q43=0,"",$R43/$Q43)
Q44: =SUM(C44,E44,G44,I44,K44,M44,O44) | R44: =SUM(D44,F44,H44,J44,L44,N44,P44) | S44: =IF($Q44=0,"",$R44/$Q44)
Q45: =SUM(C45,E45,G45,I45,K45,M45,O45) | R45: =SUM(D45,F45,H45,J45,L45,N45,P45) | S45: =IF($Q45=0,"",$R45/$Q45)
Q46: =SUM(C46,E46,G46,I46,K46,M46,O46) | R46: =SUM(D46,F46,H46,J46,L46,N46,P46) | S46: =IF($Q46=0,"",$R46/$Q46)
Q47: =SUM(C47,E47,G47,I47,K47,M47,O47) | R47: =SUM(D47,F47,H47,J47,L47,N47,P47) | S47: =IF($Q47=0,"",$R47/$Q47)
Q48: =SUM(C48,E48,G48,I48,K48,M48,O48) | R48: =SUM(D48,F48,H48,J48,L48,N48,P48) | S48: =IF($Q48=0,"",$R48/$Q48)
Q49: =SUM(C49,E49,G49,I49,K49,M49,O49) | R49: =SUM(D49,F49,H49,J49,L49,N49,P49) | S49: =IF($Q49=0,"",$R49/$Q49)
A50: TOTALES DEL AREA | C50: =SUM(C6:C49) | D50: =SUM(D6:D49) | E50: =SUM(E6:E49) | F50: =SUM(F6:F49) | G50: =SUM(G6:G49) | H50: =SUM(H6:H49) | I50: =SUM(I6:I49) | J50: =SUM(J6:J49) | ... R50: =SUM(R6:R49) | S50: =IF($Q50=0,"",$R50/$Q50)

Sheet 4 Prod Factureria
A1: PLANILLA 4 · PRODUCCION DIARIA — FACTURERÍA
A2: Jefe de area: ____________________ Semana: ____/____ al ____/____ Se elabora en: Central
A3: ELABORADO = lo que salio bueno. DESCARTE = lo que se quemo, salio mal, se cayo o se tiro. El detalle del motivo de cada descarte va en la planilla 5.
A4: PRODUCTO | B4: UNID. | C4: =IF(Config!$B$10="","LUNES",UPPER("LUN")&" "&TEXT(Config!$B$10,"dd/mm")) | E4: =IF(Config!$B$11="","MARTES",UPPER("MAR")&" "&TEXT(Config!$B$11,"dd/mm")) | G4: =IF(Config!$B$12="","MIERCOLES",UPPER("MIE")&" "&TEXT(Config!$B$12,"dd/mm")) | I4: =IF(Config!$B$13="","JUEVES",UPPER("JUE")&" "&TEXT(Config!$B$13,"dd/mm")) | K4: =IF(Config!$B$14="","VIERNES",UPPER("VIE")&" "&TEXT(Config!$B$14,"dd/mm")) | M4: =IF(Config!$B$15="","SABADO",UPPER("SAB")&" "&TEXT(Config!$B$15,"dd/mm")) | O4: =IF(Config!$B$16="","DOMINGO",UPPER("DOM")&" "&TEXT(Config!$B$16,"dd/mm")) | Q4: TOTAL ELABORADO | R4: TOTAL DESCARTE | S4: % DESC.
C5: ELABOR. | D5: DESCAR. | E5: ELABOR. | F5: DESCAR. | G5: ELABOR. | H5: DESCAR. | I5: ELABOR. | J5: DESCAR. | K5: ELABOR. | L5: DESCAR. | M5: ELABOR. | N5: DESCAR. | O5: ELABOR. | P5: DESCAR.
A6: Churros rellenos x unidad | B6: u | Q6: =SUM(C6,E6,G6,I6,K6,M6,O6) | R6: =SUM(D6,F6,H6,J6,L6,N6,P6) | S6: =IF($Q6=0,"",$R6/$Q6)
A7: Churros x unidad | B7: u | Q7: =SUM(C7,E7,G7,I7,K7,M7,O7) | R7: =SUM(D7,F7,H7,J7,L7,N7,P7) | S7: =IF($Q7=0,"",$R7/$Q7)
A8: Croissant | B8: u | Q8: =SUM(C8,E8,G8,I8,K8,M8,O8) | R8: =SUM(D8,F8,H8,J8,L8,N8,P8) | S8: =IF($Q8=0,"",$R8/$Q8)
A9: Facturas c/crema | B9: u | Q9: =SUM(C9,E9,G9,I9,K9,M9,O9) | R9: =SUM(D9,F9,H9,J9,L9,N9,P9) | S9: =IF($Q9=0,"",$R9/$Q9)
A10: Facturas c/crema y DDL | B10: u | Q10: =SUM(C10,E10,G10,I10,K10,M10,O10) | R10: =SUM(D10,F10,H10,J10,L10,N10,P10) | S10: =IF($Q10=0,"",$R10/$Q10)
A11: Facturas c/crema y membr. | B11: u | Q11: =SUM(C11,E11,G11,I11,K11,M11,O11) | R11: =SUM(D11,F11,H11,J11,L11,N11,P11) | S11: =IF($Q11=0,"",$R11/$Q11)
A12: Libritos | B12: u | Q12: =SUM(C12,E12,G12,I12,K12,M12,O12) | R12: =SUM(D12,F12,H12,J12,L12,N12,P12) | S12: =IF($Q12=0,"",$R12/$Q12)
A13: Medialunas | B13: u | Q13: =SUM(C13,E13,G13,I13,K13,M13,O13) | R13: =SUM(D13,F13,H13,J13,L13,N13,P13) | S13: =IF($Q13=0,"",$R13/$Q13)
A14: Medialunas crudas x16 | B14: u | Q14: =SUM(C14,E14,G14,I14,K14,M14,O14) | R14: =SUM(D14,F14,H14,J14,L14,N14,P14) | S14: =IF($Q14=0,"",$R14/$Q14)
A15: Medialunas saladas | B15: u | Q15: =SUM(C15,E15,G15,I15,K15,M15,O15) | R15: =SUM(D15,F15,H15,J15,L15,N15,P15) | S15: =IF($Q15=0,"",$R15/$Q15)
A16: Minifacturas | B16: kg | Q16: =SUM(C16,E16,G16,I16,K16,M16,O16) | R16: =SUM(D16,F16,H16,J16,L16,N16,P16) | S16: =IF($Q16=0,"",$R16/$Q16)
A17: Pan dulce | B17: u | Q17: =SUM(C17,E17,G17,I17,K17,M17,O17) | R17: =SUM(D17,F17,H17,J17,L17,N17,P17) | S17: =IF($Q17=0,"",$R17/$Q17)
... A21: Vigilantes | B21: u | Q21: =SUM(C21,E21,G21,I21,K21,M21,O21) | R21: =SUM(D21,F21,H21,J21,L21,N21,P21) | S21: =IF($Q21=0,"",$R21/$Q21)
Q22: =SUM(C22,E22,G22,I22,K22,M22,O22) | R22: =SUM(D22,F22,H22,J22,L22,N22,P22) | S22: =IF($Q22=0,"",$R22/$Q22)
Q23: =SUM(C23,E23,G23,I23,K23,M23,O23) | R23: =SUM(D23,F23,H23,J23,L23,N23,P23) | S23: =IF($Q23=0,"",$R23/$Q23)
Q24: =SUM(C24,E24,G24,I24,K24,M24,O24) | R24: =SUM(D24,F24,H24,J24,L24,N24,P24) | S24: =IF($Q24=0,"",$R24/$Q24)
Q25: =SUM(C25,E25,G25,I25,K25,M25,O25) | R25: =SUM(D25,F25,H25,J25,L25,N25,P25) | S25: =IF($Q25=0,"",$R25/$Q25)
Q26: =SUM(C26,E26,G26,I26,K26,M26,O26) | R26: =SUM(D26,F26,H26,J26,L26,N26,P26) | S26: =IF($Q26=0,"",$R26/$Q26)
Q27: =SUM(C27,E27,G27,I27,K27,M27,O27) | R27: =SUM(D27,F27,H27,J27,L27,N27,P27) | S27: =IF($Q27=0,"",$R27/$Q27)
Q28: =SUM(C28,E28,G28,I28,K28,M28,O28) | R28: =SUM(D28,F28,H28,J28,L28,N28,P28) | S28: =IF($Q28=0,"",$R28/$Q28)
Q29: =SUM(C29,E29,G29,I29,K29,M29,O29) | R29: =SUM(D29,F29,H29,J29,L29,N29,P29) | S29: =IF($Q29=0,"",$R29/$Q29)
A30: TOTALES DEL AREA | C30: =SUM(C6:C29) | D30: =SUM(D6:D29) | E30: =SUM(E6:E29) | F30: =SUM(F6:F29) | G30: =SUM(G6:G29) | H30: =SUM(H6:H29) | I30: =SUM(I6:I29) | J30: =SUM(J6:J29) | ... R30: =SUM(R6:R29) | S30: =IF($Q30=0,"",$R30/$Q30)

Sheet 4 Prod Sandwiches
A1: PLANILLA 4 · PRODUCCION DIARIA — SANDWICHES
A2: Jefe de area: ____________________ Semana: ____/____ al ____/____ Se elabora en: Central
A3: ELABORADO = lo que salio bueno. DESCARTE = lo que se quemo, salio mal, se cayo o se tiro. El detalle del motivo de cada descarte va en la planilla 5.
A4: PRODUCTO | B4: UNID. | C4: =IF(Config!$B$10="","LUNES",UPPER("LUN")&" "&TEXT(Config!$B$10,"dd/mm")) | E4: =IF(Config!$B$11="","MARTES",UPPER("MAR")&" "&TEXT(Config!$B$11,"dd/mm")) | G4: =IF(Config!$B$12="","MIERCOLES",UPPER("MIE")&" "&TEXT(Config!$B$12,"dd/mm")) | I4: =IF(Config!$B$13="","JUEVES",UPPER("JUE")&" "&TEXT(Config!$B$13,"dd/mm")) | K4: =IF(Config!$B$14="","VIERNES",UPPER("VIE")&" "&TEXT(Config!$B$14,"dd/mm")) | M4: =IF(Config!$B$15="","SABADO",UPPER("SAB")&" "&TEXT(Config!$B$15,"dd/mm")) | O4: =IF(Config!$B$16="","DOMINGO",UPPER("DOM")&" "&TEXT(Config!$B$16,"dd/mm")) | Q4: TOTAL ELABORADO | R4: TOTAL DESCARTE | S4: % DESC.
C5: ELABOR. | D5: DESCAR. | E5: ELABOR. | F5: DESCAR. | G5: ELABOR. | H5: DESCAR. | I5: ELABOR. | J5: DESCAR. | K5: ELABOR. | L5: DESCAR. | M5: ELABOR. | N5: DESCAR. | O5: ELABOR. | P5: DESCAR.
A6: Ciabatta de Lomito ahumado, muzzarella y rúcula con oliva | B6: u | Q6: =SUM(C6,E6,G6,I6,K6,M6,O6) | R6: =SUM(D6,F6,H6,J6,L6,N6,P6) | S6: =IF($Q6=0,"",$R6/$Q6)
A7: Ciabatta de Muzzarella, provolone, albahaca y cherrys confitados | B7: u | Q7: =SUM(C7,E7,G7,I7,K7,M7,O7) | R7: =SUM(D7,F7,H7,J7,L7,N7,P7) | S7: =IF($Q7=0,"",$R7/$Q7)
A8: Baguette de jamón cocido, queso, lechuga y tomate | B8: u | Q8: =SUM(C8,E8,G8,I8,K8,M8,O8) | R8: =SUM(D8,F8,H8,J8,L8,N8,P8) | S8: =IF($Q8=0,"",$R8/$Q8)
A9: Baguette de salame y queso | B9: u | Q9: =SUM(C9,E9,G9,I9,K9,M9,O9) | R9: =SUM(D9,F9,H9,J9,L9,N9,P9) | S9: =IF($Q9=0,"",$R9/$Q9)
A10: Miga de jamón cocido y queso | B10: u | Q10: =SUM(C10,E10,G10,I10,K10,M10,O10) | R10: =SUM(D10,F10,H10,J10,L10,N10,P10) | S10: =IF($Q10=0,"",$R10/$Q10)
A11: Miga de Ternera y tomate | B11: u | Q11: =SUM(C11,E11,G11,I11,K11,M11,O11) | R11: =SUM(D11,F11,H11,J11,L11,N11,P11) | S11: =IF($Q11=0,"",$R11/$Q11)
A12: Miga de ternera y huevo | B12: u | Q12: =SUM(C12,E12,G12,I12,K12,M12,O12) | R12: =SUM(D12,F12,H12,J12,L12,N12,P12) | S12: =IF($Q12=0,"",$R12/$Q12)
A13: Miga de crudo y queso | B13: u | Q13: =SUM(C13,E13,G13,I13,K13,M13,O13) | R13: =SUM(D13,F13,H13,J13,L13,N13,P13) | S13: =IF($Q13=0,"",$R13/$Q13)
A14: Miga de cantimpalo y queso | B14: u | Q14: =SUM(C14,E14,G14,I14,K14,M14,O14) | R14: =SUM(D14,F14,H14,J14,L14,N14,P14) | S14: =IF($Q14=0,"",$R14/$Q14)
Q15: =SUM(C15,E15,G15,I15,K15,M15,O15) | R15: =SUM(D15,F15,H15,J15,L15,N15,P15) | S15: =IF($Q15=0,"",$R15/$Q15)
Q16: =SUM(C16,E16,G16,I16,K16,M16,O16) | R16: =SUM(D16,F16,H16,J16,L16,N16,P16) | S16: =IF($Q16=0,"",$R16/$Q16)
Q17: =SUM(C17,E17,G17,I17,K17,M17,O17) | R17: =SUM(D17,F17,H17,J17,L17,N17,P17) | S17: =IF($Q17=0,"",$R17/$Q17)
Q18: =SUM(C18,E18,G18,I18,K18,M18,O18) | R18: =SUM(D18,F18,H18,J18,L18,N18,P18) | S18: =IF($Q18=0,"",$R18/$Q18)
Q19: =SUM(C19,E19,G19,I19,K19,M19,O19) | R19: =SUM(D19,F19,H19,J19,L19,N19,P19) | S19: =IF($Q19=0,"",$R19/$Q19)
Q20: =SUM(C20,E20,G20,I20,K20,M20,O20) | R20: =SUM(D20,F20,H20,J20,L20,N20,P20) | S20: =IF($Q20=0,"",$R20/$Q20)
Q21: =SUM(C21,E21,G21,I21,K21,M21,O21) | R21: =SUM(D21,F21,H21,J21,L21,N21,P21) | S21: =IF($Q21=0,"",$R21/$Q21)
Q22: =SUM(C22,E22,G22,I22,K22,M22,O22) | R22: =SUM(D22,F22,H22,J22,L22,N22,P22) | S22: =IF($Q22=0,"",$R22/$Q22)
A23: TOTALES DEL AREA | C23: =SUM(C6:C22) | D23: =SUM(D6:D22) | E23: =SUM(E6:E22) | F23: =SUM(F6:F22) | G23: =SUM(G6:G22) | H23: =SUM(H6:H22) | I23: =SUM(I6:I22) | J23: =SUM(J6:J22) | ... R23: =SUM(R6:R22) | S23: =IF($Q23=0,"",$R23/$Q23)

Sheet 4 Prod Cocina SL
A1: PLANILLA 4 · PRODUCCION DIARIA — COCINA SAN LUIS
A2: Jefe de area: ____________________ Semana: ____/____ al ____/____ Se elabora en: Local San Luis
A3: ELABORADO = lo que salio bueno. DESCARTE = lo que se quemo, salio mal, se cayo o se tiro. El detalle del motivo de cada descarte va en la planilla 5.
A4: PRODUCTO | B4: UNID. | C4: =IF(Config!$B$10="","LUNES",UPPER("LUN")&" "&TEXT(Config!$B$10,"dd/mm")) | E4: =IF(Config!$B$11="","MARTES",UPPER("MAR")&" "&TEXT(Config!$B$11,"dd/mm")) | G4: =IF(Config!$B$12="","MIERCOLES",UPPER("MIE")&" "&TEXT(Config!$B$12,"dd/mm")) | I4: =IF(Config!$B$13="","JUEVES",UPPER("JUE")&" "&TEXT(Config!$B$13,"dd/mm")) | K4: =IF(Config!$B$14="","VIERNES",UPPER("VIE")&" "&TEXT(Config!$B$14,"dd/mm")) | M4: =IF(Config!$B$15="","SABADO",UPPER("SAB")&" "&TEXT(Config!$B$15,"dd/mm")) | O4: =IF(Config!$B$16="","DOMINGO",UPPER("DOM")&" "&TEXT(Config!$B$16,"dd/mm")) | Q4: TOTAL ELABORADO | R4: TOTAL DESCARTE | S4: % DESC.
C5: ELABOR. | D5: DESCAR. | E5: ELABOR. | F5: DESCAR. | G5: ELABOR. | H5: DESCAR. | I5: ELABOR. | J5: DESCAR. | K5: ELABOR. | L5: DESCAR. | M5: ELABOR. | N5: DESCAR. | O5: ELABOR. | P5: DESCAR.
Q6: =SUM(C6,E6,G6,I6,K6,M6,O6) | R6: =SUM(D6,F6,H6,J6,L6,N6,P6) | S6: =IF($Q6=0,"",$R6/$Q6)
Q7: =SUM(C7,E7,G7,I7,K7,M7,O7) | R7: =SUM(D7,F7,H7,J7,L7,N7,P7) | S7: =IF($Q7=0,"",$R7/$Q7)
